[2024-10-10T15:34:20.309-0300] {taskinstance.py:1125} INFO - Dependencies all met for dep_context=non-requeueable deps ti=<TaskInstance: DesafioAirflow.calculate_order_count manual__2024-10-10T18:28:53.377596+00:00 [queued]>
[2024-10-10T15:34:20.323-0300] {taskinstance.py:1125} INFO - Dependencies all met for dep_context=requeueable deps ti=<TaskInstance: DesafioAirflow.calculate_order_count manual__2024-10-10T18:28:53.377596+00:00 [queued]>
[2024-10-10T15:34:20.323-0300] {taskinstance.py:1331} INFO - Starting attempt 2 of 2
[2024-10-10T15:34:20.473-0300] {taskinstance.py:1350} INFO - Executing <Task(PythonOperator): calculate_order_count> on 2024-10-10 18:28:53.377596+00:00
[2024-10-10T15:34:20.485-0300] {standard_task_runner.py:57} INFO - Started process 116939 to run task
[2024-10-10T15:34:20.501-0300] {standard_task_runner.py:84} INFO - Running: ['airflow', 'tasks', 'run', 'DesafioAirflow', 'calculate_order_count', 'manual__2024-10-10T18:28:53.377596+00:00', '--job-id', '13', '--raw', '--subdir', 'DAGS_FOLDER/example_desafio.py', '--cfg-path', '/tmp/tmpq8hx_jcd']
[2024-10-10T15:34:20.503-0300] {standard_task_runner.py:85} INFO - Job 13: Subtask calculate_order_count
[2024-10-10T15:34:20.732-0300] {task_command.py:410} INFO - Running <TaskInstance: DesafioAirflow.calculate_order_count manual__2024-10-10T18:28:53.377596+00:00 [running]> on host marti-300E5M-300E5L
[2024-10-10T15:34:21.068-0300] {taskinstance.py:1568} INFO - Exporting env vars: AIRFLOW_CTX_DAG_EMAIL='airflow@example.com' AIRFLOW_CTX_DAG_OWNER='airflow' AIRFLOW_CTX_DAG_ID='DesafioAirflow' AIRFLOW_CTX_TASK_ID='calculate_order_count' AIRFLOW_CTX_EXECUTION_DATE='2024-10-10T18:28:53.377596+00:00' AIRFLOW_CTX_TRY_NUMBER='2' AIRFLOW_CTX_DAG_RUN_ID='manual__2024-10-10T18:28:53.377596+00:00'
[2024-10-10T15:34:21.122-0300] {taskinstance.py:1847} ERROR - Task failed with exception
Traceback (most recent call last):
  File "/home/marti/Lighthouse/airflow_tooltorial/venv/lib/python3.8/site-packages/airflow/operators/python.py", line 181, in execute
    return_value = self.execute_callable()
  File "/home/marti/Lighthouse/airflow_tooltorial/venv/lib/python3.8/site-packages/airflow/operators/python.py", line 198, in execute_callable
    return self.python_callable(*self.op_args, **self.op_kwargs)
  File "/home/marti/Lighthouse/airflow_tooltorial/airflow-data/dags/example_desafio.py", line 67, in calculate_order_count
    merged_df = pd.merge(orders_df, order_details_df, on='Id')
  File "/home/marti/Lighthouse/airflow_tooltorial/venv/lib/python3.8/site-packages/pandas/core/reshape/merge.py", line 148, in merge
    op = _MergeOperation(
  File "/home/marti/Lighthouse/airflow_tooltorial/venv/lib/python3.8/site-packages/pandas/core/reshape/merge.py", line 741, in __init__
    self._maybe_coerce_merge_keys()
  File "/home/marti/Lighthouse/airflow_tooltorial/venv/lib/python3.8/site-packages/pandas/core/reshape/merge.py", line 1401, in _maybe_coerce_merge_keys
    raise ValueError(msg)
ValueError: You are trying to merge on int64 and object columns. If you wish to proceed you should use pd.concat
[2024-10-10T15:34:21.129-0300] {taskinstance.py:1368} INFO - Marking task as FAILED. dag_id=DesafioAirflow, task_id=calculate_order_count, execution_date=20241010T182853, start_date=20241010T183420, end_date=20241010T183421
[2024-10-10T15:34:21.173-0300] {logging_mixin.py:149} WARNING - /home/marti/Lighthouse/airflow_tooltorial/venv/lib/python3.8/site-packages/airflow/utils/email.py:152 RemovedInAirflow3Warning: Fetching SMTP credentials from configuration variables will be deprecated in a future release. Please set credentials using a connection instead.
[2024-10-10T15:34:21.174-0300] {configuration.py:675} WARNING - section/key [smtp/smtp_user] not found in config
[2024-10-10T15:34:21.174-0300] {email.py:268} INFO - Email alerting: attempt 1
[2024-10-10T15:34:21.181-0300] {configuration.py:675} WARNING - section/key [smtp/smtp_user] not found in config
[2024-10-10T15:34:21.183-0300] {email.py:268} INFO - Email alerting: attempt 1
[2024-10-10T15:34:21.184-0300] {taskinstance.py:1912} ERROR - Failed to send email to: ['airflow@example.com']
Traceback (most recent call last):
  File "/home/marti/Lighthouse/airflow_tooltorial/venv/lib/python3.8/site-packages/airflow/models/taskinstance.py", line 1430, in _run_raw_task
    self._execute_task_with_callbacks(context, test_mode)
  File "/home/marti/Lighthouse/airflow_tooltorial/venv/lib/python3.8/site-packages/airflow/models/taskinstance.py", line 1581, in _execute_task_with_callbacks
    result = self._execute_task(context, task_orig)
  File "/home/marti/Lighthouse/airflow_tooltorial/venv/lib/python3.8/site-packages/airflow/models/taskinstance.py", line 1651, in _execute_task
    result = execute_callable(context=context)
  File "/home/marti/Lighthouse/airflow_tooltorial/venv/lib/python3.8/site-packages/airflow/operators/python.py", line 181, in execute
    return_value = self.execute_callable()
  File "/home/marti/Lighthouse/airflow_tooltorial/venv/lib/python3.8/site-packages/airflow/operators/python.py", line 198, in execute_callable
    return self.python_callable(*self.op_args, **self.op_kwargs)
  File "/home/marti/Lighthouse/airflow_tooltorial/airflow-data/dags/example_desafio.py", line 67, in calculate_order_count
    merged_df = pd.merge(orders_df, order_details_df, on='Id')
  File "/home/marti/Lighthouse/airflow_tooltorial/venv/lib/python3.8/site-packages/pandas/core/reshape/merge.py", line 148, in merge
    op = _MergeOperation(
  File "/home/marti/Lighthouse/airflow_tooltorial/venv/lib/python3.8/site-packages/pandas/core/reshape/merge.py", line 741, in __init__
    self._maybe_coerce_merge_keys()
  File "/home/marti/Lighthouse/airflow_tooltorial/venv/lib/python3.8/site-packages/pandas/core/reshape/merge.py", line 1401, in _maybe_coerce_merge_keys
    raise ValueError(msg)
ValueError: You are trying to merge on int64 and object columns. If you wish to proceed you should use pd.concat

During handling of the above exception, another exception occurred:

Traceback (most recent call last):
  File "/home/marti/Lighthouse/airflow_tooltorial/venv/lib/python3.8/site-packages/airflow/models/taskinstance.py", line 2318, in email_alert
    send_email(task.email, subject, html_content)
  File "/home/marti/Lighthouse/airflow_tooltorial/venv/lib/python3.8/site-packages/airflow/utils/email.py", line 78, in send_email
    return backend(
  File "/home/marti/Lighthouse/airflow_tooltorial/venv/lib/python3.8/site-packages/airflow/utils/email.py", line 152, in send_email_smtp
    send_mime_email(e_from=mail_from, e_to=recipients, mime_msg=msg, conn_id=conn_id, dryrun=dryrun)
  File "/home/marti/Lighthouse/airflow_tooltorial/venv/lib/python3.8/site-packages/airflow/utils/email.py", line 270, in send_mime_email
    smtp_conn = _get_smtp_connection(smtp_host, smtp_port, smtp_timeout, smtp_ssl)
  File "/home/marti/Lighthouse/airflow_tooltorial/venv/lib/python3.8/site-packages/airflow/utils/email.py", line 317, in _get_smtp_connection
    else smtplib.SMTP(host=host, port=port, timeout=timeout)
  File "/usr/lib/python3.8/smtplib.py", line 255, in __init__
    (code, msg) = self.connect(host, port)
  File "/usr/lib/python3.8/smtplib.py", line 339, in connect
    self.sock = self._get_socket(host, port, self.timeout)
  File "/usr/lib/python3.8/smtplib.py", line 310, in _get_socket
    return socket.create_connection((host, port), timeout,
  File "/usr/lib/python3.8/socket.py", line 808, in create_connection
    raise err
  File "/usr/lib/python3.8/socket.py", line 796, in create_connection
    sock.connect(sa)
ConnectionRefusedError: [Errno 111] Connection refused

During handling of the above exception, another exception occurred:

Traceback (most recent call last):
  File "/home/marti/Lighthouse/airflow_tooltorial/venv/lib/python3.8/site-packages/airflow/models/taskinstance.py", line 1910, in handle_failure
    self.email_alert(error, task)
  File "/home/marti/Lighthouse/airflow_tooltorial/venv/lib/python3.8/site-packages/airflow/models/taskinstance.py", line 2320, in email_alert
    send_email(task.email, subject, html_content_err)
  File "/home/marti/Lighthouse/airflow_tooltorial/venv/lib/python3.8/site-packages/airflow/utils/email.py", line 78, in send_email
    return backend(
  File "/home/marti/Lighthouse/airflow_tooltorial/venv/lib/python3.8/site-packages/airflow/utils/email.py", line 152, in send_email_smtp
    send_mime_email(e_from=mail_from, e_to=recipients, mime_msg=msg, conn_id=conn_id, dryrun=dryrun)
  File "/home/marti/Lighthouse/airflow_tooltorial/venv/lib/python3.8/site-packages/airflow/utils/email.py", line 270, in send_mime_email
    smtp_conn = _get_smtp_connection(smtp_host, smtp_port, smtp_timeout, smtp_ssl)
  File "/home/marti/Lighthouse/airflow_tooltorial/venv/lib/python3.8/site-packages/airflow/utils/email.py", line 317, in _get_smtp_connection
    else smtplib.SMTP(host=host, port=port, timeout=timeout)
  File "/usr/lib/python3.8/smtplib.py", line 255, in __init__
    (code, msg) = self.connect(host, port)
  File "/usr/lib/python3.8/smtplib.py", line 339, in connect
    self.sock = self._get_socket(host, port, self.timeout)
  File "/usr/lib/python3.8/smtplib.py", line 310, in _get_socket
    return socket.create_connection((host, port), timeout,
  File "/usr/lib/python3.8/socket.py", line 808, in create_connection
    raise err
  File "/usr/lib/python3.8/socket.py", line 796, in create_connection
    sock.connect(sa)
ConnectionRefusedError: [Errno 111] Connection refused
[2024-10-10T15:34:21.336-0300] {standard_task_runner.py:104} ERROR - Failed to execute job 13 for task calculate_order_count (You are trying to merge on int64 and object columns. If you wish to proceed you should use pd.concat; 116939)
[2024-10-10T15:34:21.388-0300] {local_task_job_runner.py:232} INFO - Task exited with return code 1
[2024-10-10T15:34:21.428-0300] {taskinstance.py:2674} INFO - 0 downstream tasks scheduled from follow-on schedule check
